Workbook
Name _bookmark28: Guidance!$B$43
Name _bookmark32: Guidance!$B$44
Name _Toc112658799: Guidance!#REF!
Name _Toc112658800: Guidance!$B$15
Name _Toc112658801: Guidance!$B$16
Name _Toc112658802: Guidance!$B$20
Name _Toc112658803: Guidance!$B$23
Name _Toc112658804: Guidance!$B$27
Name _Toc112658805: Guidance!$B$41
Name _Toc112658807: Guidance!$B$60
Name _Toc112671323: Guidance!$B$2
Name _Toc112671324: Guidance!$B$3
Name _Toc50979603: 'Building Register'!$A$1
Name _Toc50979604: 'Intangible Asset Register '!$A$1
Name _Toc50979605: 'Stocks Consumables Register '!#REF!
Name _Toc50979606: 'Railway register '!$A$1
Name _Toc50979607: 'Roads Infastructure register '!$A$1
Name _Toc50979608: 'Other Infastructure register '!$A$1
Name _Toc50979609: 'Biological register '!$A$1
Name _Toc50979610: 'Subsoil register '!$A$1
Name _Toc50979611: 'Major maintenance register '!$A$1
Name _Toc50979612: 'Work in progress register '!$A$1
Name _Toc50979614: 'Cash register '!$A$1
Name _Toc50979615: 'Bank register '!$A$1
Name _Toc50979616: 'Loans receivables register'!$A$1
Name _Toc50979617: 'Accounts receivables register '!$A$1
Name _Toc50979618: 'Other receivables register '!$A$1
Name _Toc50979619: 'Imprest register '!$A$1
Name _Toc50979620: 'Loans payable register '!$A$1
Name _Toc50979621: 'contigent Liabities register'!$A$1
Name _Toc50979622: 'Accruals register '!$A$1
Name _Toc50979623: 'Accounts payable register '!$A$1
Name _Toc50979624: 'Pensions payable register'!$A$1
Name _Toc50979625: 'Other liabilities register '!$A$1
Name _Toc50979626: 'Asset movement form'!$A$1
Name _Toc50979627: 'Revaluation Schedule '!$A$1
Name _Toc50979628: 'Losses Register '!$A$1
Name _Toc50979629: 'Guarantees &indeminities '!$A$1
Name _Toc50979630: 'Lease register '!$A$1
Name _Toc50979631: 'Litigation Register '!$A$2
Name _Toc50979632: 'Equipment sign out register '!$A$1
Name _Toc50979633: 'Asset transfer form '!$A$1
Name _Toc50979634: 'Asset Handover form'!$A$1
Name _Toc50979635: 'Asset reconciliation report '!$A$1

Sheet Guidance
B2: ASSET AND LIABLILITY REPORTING TEMPLATES
B4: General
B5: Mode of acquisition - mode of acquisition may be through purchase, transfer, donation etc
B8: Land register
B9: Polygon under the land register refers to the GPS readings of the four corners of a plot of land
B10: Encumbrances under the land register refers to any caveats placed on a plot of land
B11: Planned / unplanned in the land register refers to whether the plot of land is located in an area that has formal plans or otherwise
B13: Intangible assets
B14: Intangible assets - Documents of ownership include copyrights, patents for intellectual property; also special access rights for software
B16: 1.All Accounting officers are supposed to ensure that their entity has documents of ownership for its property. Where an entity is a body corporate, the documents of ownership should be in the name of the entity and under the custody of the Accounting Officer
B17: 2.All MDAs are required to submit quarterly and annual reports to The National Treasury & Planning using the prescribed format.
B18: 3.Public Sector entities will be required to submit their Quaterly reports for asset management structures, ownership documents and asset registers should be submitted quarterly by 15th of the subsequent month after every quarter. and annual disposal plans by 15th of October of the financial year.

Sheet Table of Contents
A1: Guidance
A2: Table of Contents
A3: Land Register
A4: Building Register
A5: Motor Vehicle Register
A6: Office equipment register
A7: ICT Computer Register
A8: Furniture&Fittings
A9: Plant &Machinery Register
A10: Portable &attractive Items
A11: Intangible Asset Register
A12: Stocks Consumables Register
... A42: Asset reconciliation report

Sheet Land Register 
A1: Land Register | B1: Land Register
A2: Description of land | B2: Mode of Acquisition e.g. purchase, transfer, donation etc. | C2: Category (Land or investment property) | D2: County | E2: Nearest town/ Location | F2: GPS | G2: Polygon* | K2: L.R /certifcate No. Or other unique identifier | L2: Document of ownership held (Title deed, certificate, allotment letter, etc.) | M2: Proprietorship/ ownership details as per document of title | N2: Size (ha) | O2: Ownership status (Freehold /leasehold) | P2: Acquisition date | Q2: Registration date | R2: Disputed/ undisputed | S2: Encumberances | T2: Planned/ Unplanned | U2: Purpose/ Use of land | V2: Surveyed/ Not surveyed | W2: Acquisition Amount | X2: Fair value/ Ministry of Lands zonal maps or land index | Y2: Disposal date/ Change of use date | Z2: Disposal value | AA2: Annual rental income (for investment property) | AB2: Remarks
G3: A | H3: B | I3: C | J3: D
A4: None | B4: None | C4: None | D4: None | E4: None | F4: None | G4: None | H4: None | I4: None | J4: None | K4: None | L4: None | M4: None | N4: None | O4: None | P4: None | Q4: None | R4: None | S4: None | T4: None | U4: None | V4: None | W4: None | X4: None
A10: Prepared by: Doris Muthini Designation: Manager SCM Date: 30th June 2025
A11: Checked by: David NjaneDesignation: Finance Manager Date: 30th June 2025
A12: Authorized by: Dr. Laxmana P. Kiptoo Designation: Director/Chief Executive Officer Date: 30th June 2025

Sheet Building Register
A1: Buildings Register
B2: Description/ Name of building | C2: Building ownership | D2: Category (Building or investment property) | E2: Building No. | F2: Institution No. | G2: Nearest town/ Shopping centre | H2: Street | I2: County | J2: L.R N o. | K2: Size of land (ha) | L2: Ownership status (Freehold/ leasehold) | M2: Source of funds | N2: Mode of acquisition | O2: Date of purchase/ Building commisssioning (for constructed buildings) | P2: Type of building (Permanent/ temporary) | Q2: Designated use | R2: Estimated useful life | S2: No. of floors | T2: Plinth Area | U2: Cost of construction/ Valuation | V2: Annual depreciation | W2: Estimated useful life | X2: Accumulated depreciation to date | Y2: Net Book value | Z2: Annual rental income (for investment property) | AA2: Remarks
A3: 1 | B3: None | C3: None | D3: None | E3: None | F3: None | G3: None | H3: None | I3: None | J3: None | K3: None | L3: None | M3: None | N3: None | O3: None | P3: None | Q3: None | R3: None | S3: None | T3: None | U3: None | V3: None | W3: None | X3: None | Y3: None | Z3: None
A4: 2
A5: 3
A6: 4
A7: 5
A10: Prepared by: Doris Muthini Designation: Manager SCM Date: 30th June 2025
A11: Checked by: David NjaneDesignation: Finance Manager Date: 30th June 2025
A12: Authorized by: Dr. Laxmana P. Kiptoo Designation: Director/Chief Executive Officer Date: 30th June 2025

Sheet Motor Vehicle Register
A1: Motor vehicle Register
A2: No. | B2: Vehicle Registration No. | C2: Financed by/ source of funds | D2: Engine No. | E2: Chassis No. | F2: Tag number/ | G2: Make & Model | H2: Year of purchase | I2: PV number | J2: Original Location | K2: Current Location | L2: Replacement Date (if applicable) | M2: Amount | N2: Depreciation rate | O2: Annual depreciation | P2: Accumulated depreciation | Q2: Net Book Value | R2: Date of disposal | S2: Disposal value | T2: Responsible officer | U2: Asset condition | V2: Does the MV have a log book(Y/N) | W2: Notes
A3: 1 | B3: KCT 857Y | C3: GOK | D3: CNF097931 | E3: WV1ZZZ2HZJA041835 | F3: NGOB/04/0002 | G3: Volkswagen Amarok DC 4x4 MT 103 Comfortline | H3: 2020 | I3: 18/20/21 | J3: Nairobi | K3: Nairobi | L3: 2029 | M3: 6655350 | N3: 0.25 | O3: =P3/(2025-H3) -> 1015200.9 | P3: =M3-Q3 -> 5076004.3 | Q3: =M3*(1-N3)^(2025-H3) -> 1579345.8 | R3: 2033 | T3: Senior Officer Administration | U3: Good | V3: Y
A4: 2 | B4: KCT 859Y | C4: GOK | D4: CNF1121315 | E4: WV1ZZZ2HZKA041160 | F4: NGOB/04/0003 | G4: Volkswagen Amarok DC 4x4 MT 103 Comfortline | H4: 2020 | I4: 18/20/21 | J4: Nairobi | K4: Nairobi | L4: 2029 | M4: 6655350 | N4: 0.25 | O4: =P4/(2025-H4) -> 1015200.9 | P4: =M4-Q4 -> 5076004.3 | Q4: =M4*(1-N4)^(2025-H4) -> 1579345.8 | R4: 2033 | T4: Senior Officer Administration | U4: Good | V4: Y
A5: 3 | B5: KCT 856Y | C5: GOK | D5: CNF112493 | E5: WV1ZZZ2HZKAO40798 | F5: NGOB/04/0004 | G5: Volkswagen Amarok DC 4x4 MT 103 Comfortline | H5: 2020 | I5: 18/20/21 | J5: Nairobi | K5: Nairobi | L5: 2029 | M5: 6655350 | N5: 0.25 | O5: =P5/(2025-H5) -> 1015200.9 | P5: =M5-Q5 -> 5076004.3 | Q5: =M5*(1-N5)^(2025-H5) -> 1579345.8 | R5: 2033 | T5: Senior Officer Administration | U5: Good | V5: Y
A6: 4 | B6: KCT 858Y | C6: GOK | D6: CNF111885 | E6: WV1ZZZ2HZKA039232 | F6: NGOB/04/0001 | G6: Volkswagen Amarok DC 4x4 MT 103 Comfortline | H6: 2020 | I6: 18/20/21 | J6: Nairobi | K6: Nairobi | L6: 2029 | M6: 6655350 | N6: 0.25 | O6: =P6/(2025-H6) -> 1015200.9 | P6: =M6-Q6 -> 5076004.3 | Q6: =M6*(1-N6)^(2025-H6) -> 1579345.8 | R6: 2033 | T6: Senior Officer Administration | U6: Good | V6: Y
A7: 5 | B7: KCT 885Y | C7: GOK | D7: 1KDB051337 | E7: JTEBH3FJ70K229360 | F7: NGOB/04/0005 | G7: 3.0 L/Cruiser Prado KDJI50R-GKAEY | H7: 2020 | I7: 19/20/21 | J7: Nairobi | K7: Nairobi | L7: 2029 | M7: 10977414 | N7: 0.25 | O7: =P7/(2025-H7) -> 1674484.4 | P7: =M7-Q7 -> 8372422.2 | Q7: =M7*(1-N7)^(2025-H7) -> 2604991.8 | R7: 2033 | T7: Senior Officer Administration | U7: Good | V7: Y
A8: 6 | B8: KCT 903Y | C8: GOK | D8: 1KD-B043708 | E8: JTEBH3FJ20K227788 | F8: NGOB/04/0006 | G8: 3.0 L/Cruiser Prado KDJI50R-GKAEY | H8: 2020 | I8: 20/20/21 | J8: Nairobi | K8: Nairobi | L8: 2029 | M8: 10977414 | N8: 0.25 | O8: =P8/(2025-H8) -> 1674484.4 | P8: =M8-Q8 -> 8372422.2 | Q8: =M8*(1-N8)^(2025-H8) -> 2604991.8 | R8: 2033 | T8: Senior Officer Administration | U8: Good | V8: Y
A9: 7 | B9: KCT 853Y | C9: GOK | D9: CNF097931 | E9: WVIZZZ2HZJA041835 | F9: NGOB/04/0007 | G9: Toyota Rush F800RE-GQGF | H9: 2020 | I9: 21/20/21 | J9: Nairobi | K9: Nairobi | L9: 2029 | M9: 3555621 | N9: 0.25 | O9: =P9/(2025-H9) -> 542371.09 | P9: =M9-Q9 -> 2711855.5 | Q9: =M9*(1-N9)^(2025-H9) -> 843765.53 | R9: 2033 | T9: Senior Officer Administration | U9: Good | V9: Y
A10: 8 | B10: KCT 844Y | C10: GOK | D10: 2KD-B026547 | E10: JTFSS22P900188937 | F10: NGOB/04/0008 | G10: Hiace Mini bus KDH222R-LEMDY | H10: 2020 | I10: 22/20/21 | J10: Nairobi | K10: Nairobi | L10: 2029 | M10: 5218448 | N10: 0.25 | O10: =P10/(2025-H10) -> 796017.17 | P10: =M10-Q10 -> 3980085.8 | Q10: =M10*(1-N10)^(2025-H10) -> 1238362.2 | R10: 2033 | T10: Senior Officer Administration | U10: Good | V10: Y
M11: =SUM(M3:M10) -> 57350297 | O11: =SUM(O3:O10) -> 8748160.5 | P11: =SUM(P3:P10) -> 43740803 | Q11: =SUM(Q3:Q10) -> 13609494
A13: Prepared by: Doris Muthini Designation: Manager SCM Date: 30th June 2025
A14: Checked by: David NjaneDesignation: Finance Manager Date: 30th June 2025
A15: Authorized by: Dr. Laxmana P. Kiptoo Designation: Director/Chief Executive Officer Date: 30th June 2025

Sheet Office equipment register 
A1: Asset Description | B1: Financed by/ source of funds | C1: Serial number | D1: Tag number | E1: Make & Model | F1: Date of Delivery / installation | G1: PV number | H1: Original Location | I1: Current Location | J1: Replacement Date (if applicable) | K1: Purchase amount | L1: 0.125 | M1: Annual depreciation | N1: Accumulated depreciation | O1: Net Book Value | P1: Date of disposal | Q1: Disposal value | R1: Responsible officer | S1: Asset condition | T1: Notes
A2: TYPE WRITER | B2: GOK | C2: N/A | D2: NGOB/03/0092 | E2: IBM Wheel writer 50 Series | F2: 2017 | H2: Nairobi | I2: Nairobi | J2: 2023 | K2: 137500 | L2: 0.125 | M2: =N2/(2025-F2) -> 11281.722 | N2: =K2-O2 -> 90253.774 | O2: =K2*(1-L2)^(2025-F2) -> 47246.226 | R2: Margret Mwai | S2: Good | T2: In Use
A3: SERVER | B3: GOK | C3: B1WYT2 | D3: NGOB/03/0081 | E3: POWER EDGE 2950,QUAD CORE, 32GB,600GB | F3: 2008 | H3: Nairobi | I3: Nairobi | J3: 2023 | K3: 108936 | L3: 0.125 | M3: =N3/(2025-F3) -> 5745.9978 | N3: =K3-O3 -> 97681.963 | O3: =K3*(1-L3)^(2025-F3) -> 11254.037 | R3: Admistration Officer | S3: Good | T3: In Use
A4: SERVER | B4: GOK | C4: J308EM3 | D4: NGOB/03/0083 | E4: IBM Lenovo, 8 core 3.5Ghz x2, 146GB, 6TB | F4: 2016 | H4: Nairobi | I4: Nairobi | J4: 2023 | K4: 3701817 | L4: 0.125 | M4: =N4/(2025-F4) -> 287648.54 | N4: =K4-O4 -> 2588836.8 | O4: =K4*(1-L4)^(2025-F4) -> 1112980.2 | R4: Admistration Officer | S4: Good | T4: In Use
A5: FRIDGE | B5: GOK | D5: NGOB/03/0125 | E5: Internet cabinet | H5: Kisumu | I5: Kisumu | K5: 26000 | L5: 0.125 | M5: =N5/(2025-F5) -> 12.839506 | N5: =K5-O5 -> 26000 | O5: =K5*(1-L5)^(2025-F5) -> 9.5781298e-114 | R5: Admistration Officer | S5: Good | T5: In Use
A6: Internet cabinet | B6: GOK | D6: NGOB/03/0107 | E6: Internet cabinet | H6: Kisumu | I6: Kisumu | K6: 26000 | L6: 0.125 | M6: =N6/(2025-F6) -> 12.839506 | N6: =K6-O6 -> 26000 | O6: =K6*(1-L6)^(2025-F6) -> 9.5781298e-114 | R6: Admistration Officer | S6: Good | T6: In Use
A7: SERVER | B7: GOK | C7: CKDTD5J | D7: NGOB/03/0082 | E7: POWER EDGE R710,QUAD CORE, 192GB, 1.5TB | F7: 2012 | H7: Nairobi | I7: Nairobi | J7: 2023 | K7: 1470874 | L7: 0.125 | M7: =N7/(2025-F7) -> 93203.619 | N7: =K7-O7 -> 1211647 | O7: =K7*(1-L7)^(2025-F7) -> 259226.96 | R7: Admistration Officer | S7: Good | T7: In Use
A8: SERVER | B8: GOK | C8: CZ21110271 | D8: NGOB/03/0042 | E8: HP Proliant DL380 Gen10 | F8: 2021 | H8: Nairobi | I8: Nairobi | J8: 2024 | K8: 4630000 | L8: 0.125 | M8: =N8/(2025-F8) -> 478994.75 | N8: =K8-O8 -> 1915979 | O8: =K8*(1-L8)^(2025-F8) -> 2714021 | R8: Admistration Officer | S8: Good | T8: In Use
A9: SERVER | B9: GOK | C9: CZ21110255 | D9: NGOB/03/0223 | E9: HP Proliant DL380 Gen10 | F9: 2021 | H9: Nairobi | I9: Nairobi | J9: 2024 | K9: 4630000 | L9: 0.125 | M9: =N9/(2025-F9) -> 478994.75 | N9: =K9-O9 -> 1915979 | O9: =K9*(1-L9)^(2025-F9) -> 2714021 | R9: Admistration Officer | S9: Good | T9: In Use
A10: ROUTER | B10: GOK | C10: C6910CD3D8E6/017/r2 | D10: NGOB/03/0078 | E10: Mikrotik RB201 | F10: 2021 | H10: Nairobi | I10: Nairobi | J10: 2024 | K10: 147168 | L10: 0.125 | M10: =N10/(2025-F10) -> 15225.205 | N10: =K10-O10 -> 60900.82 | O10: =K10*(1-L10)^(2025-F10) -> 86267.18 | R10: Admistration Officer | S10: Good | T10: In Use
A11: LAN installation | B11: GOK | C11: N/A | E11: Network Cabling Installation and Commissioning | F11: 2021 | H11: Nairobi | I11: Nairobi | J11: 2024 | K11: 7243896 | L11: 0.125 | M11: =N11/(2025-F11) -> 749414.29 | N11: =K11-O11 -> 2997657.2 | O11: =K11*(1-L11)^(2025-F11) -> 4246238.8 | R11: Admistration Officer | S11: Good | T11: In Use
A12: Internet cabinet | B12: GOK | C12: N/A | D12: NGOB/03/00100 | E12: Internet cabinet | F12: 2021 | H12: Mombasa | I12: Mombasa | J12: 2024 | K12: 26000 | L12: 0.125 | M12: =N12/(2025-F12) -> 2689.8193 | N12: =K12-O12 -> 10759.277 | O12: =K12*(1-L12)^(2025-F12) -> 15240.723 | R12: Admistration Officer | S12: Good | T12: In Use
A13: Internet cabinet | B13: GOK | C13: N/A | D13: NGOB/03/0114 | E13: Internet cabinet | F13: 2021 | H13: Nakuru | I13: Nakuru | J13: 2024 | K13: 26000 | L13: 0.125 | M13: =N13/(2025-F13) -> 2689.8193 | N13: =K13-O13 -> 10759.277 | O13: =K13*(1-L13)^(2025-F13) -> 15240.723 | R13: Admistration Officer | S13: Good | T13: In Use
A14: Microwave | B14: GOK | C14: N/A | D14: NGOB/03/0072 | E14: Microwave | F14: 2021 | H14: Mombasa | I14: Mombasa | J14: 2024 | K14: 18000 | L14: 0.125 | M14: =N14/(2025-F14) -> 1862.1826 | N14: =K14-O14 -> 7448.7305 | O14: =K14*(1-L14)^(2025-F14) -> 10551.27 | R14: Admistration Officer | S14: Good | T14: In Use
A15: Water dispenser | B15: GOK | C15: N/A | D15: NGOB/03/0062 | E15: Water dispensor | F15: 2021 | H15: Garisa | I15: Garisa | J15: 2021 | K15: 27675 | L15: 0.125 | M15: =N15/(2025-F15) -> 2863.1058 | N15: =K15-O15 -> 11452.423 | O15: =K15*(1-L15)^(2025-F15) -> 16222.577 | R15: Admistration Officer | S15: Good | T15: In Use
A16: Water dispenser | B16: GOK | C16: N/A | D16: NGOB/03/0108 | E16: Water dispensor | F16: 2021 | H16: Eldoret | I16: Eldoret | J16: 2021 | K16: 27675 | L16: 0.125 | M16: =N16/(2025-F16) -> 2863.1058 | N16: =K16-O16 -> 11452.423 | O16: =K16*(1-L16)^(2025-F16) -> 16222.577 | R16: Admistration Officer | S16: Good | T16: In Use
A17: Dispencer | B17: GOK | C17: N/A | D17: NGOB/03/0101 | E17: Water dispensor | F17: 2021 | H17: Kisumu | I17: Kisumu | J17: 2021 | K17: 27675 | L17: 0.125 | M17: =N17/(2025-F17) -> 2863.1058 | N17: =K17-O17 -> 11452.423 | O17: =K17*(1-L17)^(2025-F17) -> 16222.577 | R17: Admistration Officer | S17: Good | T17: In Use
A18: Bulk fillin system | C18: N/A | D18: NGOB/01/096 | E18: Bulky filling system | F18: 2014 | H18: Nairobi | I18: Nairobi | K18: 816000 | L18: 0.125 | M18: =N18/(2025-F18) -> 57105.822 | N18: =K18-O18 -> 628164.04 | O18: =K18*(1-L18)^(2025-F18) -> 187835.96 | R18: Charles Mugo | S18: Good | T18: In Use
A19: Bulk fillin system | C19: N/A | D19: NGOB/01/0086-0090 | E19: Bulky filling system | F19: 2020 | H19: Nairobi | I19: Nairobi | K19: 2837161 | L19: 0.125 | M19: =N19/(2025-F19) -> 276391.15 | N19: =K19-O19 -> 1381955.8 | O19: =K19*(1-L19)^(2025-F19) -> 1455205.2 | R19: Charles Mugo | S19: Good | T19: In Use
A20: Office Safe | B20: GOK | C20: N/A | D20: NGOB/03/0093 | E20: Office Safe | F20: 2021 | H20: Nairobi | I20: Nairobi | K20: 90000 | L20: 0.125 | M20: =N20/(2025-F20) -> 9310.9131 | N20: =K20-O20 -> 37243.652 | O20: =K20*(1-L20)^(2025-F20) -> 52756.348 | R20: Dorris Muthini | S20: Good | T20: In Use
A21: Office Safe | E21: Office Safe | F21: 2021 | H21: Nairobi | I21: Nairobi | K21: 90000 | L21: 0.125 | M21: =N21/(2025-F21) -> 9310.9131 | N21: =K21-O21 -> 37243.652 | O21: =K21*(1-L21)^(2025-F21) -> 52756.348 | R21: Muktar Mohammed | S21: Good | T21: In Use
A22: Filling cabinets | B22: GOK | C22: N/A | D22: NGOB/01/0289 | E22: Mettalic 4 drawer cabinet | F22: 2021 | H22: Nairobi | I22: Nairobi | K22: 29450 | L22: 0.125 | M22: =N22/(2025-F22) -> 3046.7377 | N22: =K22-O22 -> 12186.951 | O22: =K22*(1-L22)^(2025-F22) -> 17263.049 | R22: Elizabeth Kamau | S22: Good | T22: In Use
A23: Filling cabinets | B23: GOK | C23: N/A | D23: NGOB/01/0336 | E23: Mettalic 4 drawer cabinet | F23: 2021 | H23: Nairobi | I23: Nairobi | K23: 34162 | L23: 0.125 | M23: =N23/(2025-F23) -> 3534.2157 | N23: =K23-O23 -> 14136.863 | O23: =K23*(1-L23)^(2025-F23) -> 20025.137 | R23: Arasa Mokuah | S23: Good | T23: In Use
A24: Filling cabinets | B24: GOK | C24: N/A | D24: NGOB/01/0331 | E24: Mettalic double door | F24: 2021 | H24: Nairobi | I24: Nairobi | K24: 34162 | L24: 0.125 | M24: =N24/(2025-F24) -> 3534.2157 | N24: =K24-O24 -> 14136.863 | O24: =K24*(1-L24)^(2025-F24) -> 20025.137 | R24: Dorris Muthini | S24: Good | T24: In Use
A25: Filling cabinets | B25: GOK | C25: N/A | D25: NGOB/01/0133 | E25: Mettalic 4 drawer cabinet | F25: 2021 | H25: Nairobi | I25: Nairobi | K25: 29450 | L25: 0.125 | M25: =N25/(2025-F25) -> 3046.7377 | N25: =K25-O25 -> 12186.951 | O25: =K25*(1-L25)^(2025-F25) -> 17263.049 | R25: Beatrice Topisa | S25: Good | T25: In Use
A26: Filling cabinets | B26: GOK | C26: N/A | D26: NGOB/01/0313 | E26: Mettalic 4 drawer cabinet | F26: 2021 | H26: Nairobi | I26: Nairobi | K26: 34162 | L26: 0.125 | M26: =N26/(2025-F26) -> 3534.2157 | N26: =K26-O26 -> 14136.863 | O26: =K26*(1-L26)^(2025-F26) -> 20025.137 | R26: Berly Odete | S26: Good | T26: In Use
A27: Filling cabinets | B27: GOK | C27: N/A | D27: NGOB/01/0314 | E27: Mettalic 4 drawer cabinet | F27: 2021 | H27: Nairobi | I27: Nairobi | K27: 34162 | L27: 0.125 | M27: =N27/(2025-F27) -> 3534.2157 | N27: =K27-O27 -> 14136.863 | O27: =K27*(1-L27)^(2025-F27) -> 20025.137 | R27: Berly Odete | S27: Good | T27: In Use
A28: Filling cabinets | B28: GOK | C28: N/A | D28: NGOB/01/0315 | E28: Mettalic 4 drawer cabinet | F28: 2021 | H28: Nairobi | I28: Nairobi | K28: 34162 | L28: 0.125 | M28: =N28/(2025-F28) -> 3534.2157 | N28: =K28-O28 -> 14136.863 | O28: =K28*(1-L28)^(2025-F28) -> 20025.137 | R28: Berly Odete | S28: Good | T28: In Use
A29: Filling cabinets | B29: GOK | C29: N/A | D29: NGOB/01/0434 | E29: Mettalic 4 drawer cabinet | F29: 2021 | H29: Nairobi | I29: Nairobi | K29: 34162 | L29: 0.125 | M29: =N29/(2025-F29) -> 3534.2157 | N29: =K29-O29 -> 14136.863 | O29: =K29*(1-L29)^(2025-F29) -> 20025.137 | R29: Isaiah Sang | S29: Good | T29: In Use
A30: Filling cabinets | B30: GOK | C30: N/A | D30: NGOB/01/0389 | E30: Mettalic 4 drawer cabinet | F30: 2021 | H30: Nairobi | I30: Nairobi | K30: 34162 | L30: 0.125 | M30: =N30/(2025-F30) -> 3534.2157 | N30: =K30-O30 -> 14136.863 | O30: =K30*(1-L30)^(2025-F30) -> 20025.137 | R30: Judy Njiru | S30: Good | T30: In Use
A31: Filling cabinets | B31: GOK | C31: N/A | D31: NGOB/01/0379 | E31: Mettalic 4 drawer cabinet | F31: 2021 | H31: Nairobi | I31: Nairobi | K31: 29450 | L31: 0.125 | M31: =N31/(2025-F31) -> 3046.7377 | N31: =K31-O31 -> 12186.951 | O31: =K31*(1-L31)^(2025-F31) -> 17263.049 | R31: Ephy Nafuna | S31: Good | T31: In Use
A32: Filling cabinets | B32: GOK | C32: N/A | D32: NGOB/01/0378 | E32: Mettalic 4 drawer cabinet | F32: 2021 | H32: Nairobi | I32: Nairobi | K32: 29450 | L32: 0.125 | M32: =N32/(2025-F32) -> 3046.7377 | N32: =K32-O32 -> 12186.951 | O32: =K32*(1-L32)^(2025-F32) -> 17263.049 | R32: Ephy Nafuna | S32: Good | T32: In Use
A33: Filling cabinets | B33: GOK | C33: N/A | D33: NGOB/01/0150 | E33: Mettalic 4 drawer cabinet | F33: 2021 | H33: Nairobi | I33: Nairobi | K33: 34162 | L33: 0.125 | M33: =N33/(2025-F33) -> 3534.2157 | N33: =K33-O33 -> 14136.863 | O33: =K33*(1-L33)^(2025-F33) -> 20025.137 | R33: Ephy Nafuna | S33: Good | T33: In Use
... A48: Water dispenser | B48: GOK | C48: N/A | D48: NGOB/03/0066 | E48: Water dispenser | F48: 2021 | H48: Nairobi | I48: Nairobi | K48: 32099 | L48: 0.125 | M48: =N48/(2025-F48) -> 3320.7889 | N48: =K48-O48 -> 13283.156 | O48: =K48*(1-L48)^(2025-F48) -> 18815.844 | R48: Elizabeth Kamau | S48: Good | T48: In Use
A49: Water dispenser | B49: GOK | C49: N/A | D49: NGOB/03/0016 | E49: Water dispenser | F49: 2021 | H49: Nairobi | I49: Nairobi | K49: 32099 | L49: 0.125 | M49: =N49/(2025-F49) -> 3320.7889 | N49: =K49-O49 -> 13283.156 | O49: =K49*(1-L49)^(2025-F49) -> 18815.844 | R49: Elizabeth Kamau | T49: In Use
A50: Water dispenser | B50: GOK | C50: N/A | E50: Water dispenser | F50: 2023 | H50: Nairobi | I50: Nairobi | K50: 16495 | L50: 0.125 | M50: =N50/(2025-F50) -> 1933.0078 | N50: =K50-O50 -> 3866.0156 | O50: =K50*(1-L50)^(2025-F50) -> 12628.984 | R50: Elizabeth Kamau | T50: In Use
A51: Water dispenser | B51: GOK | C51: N/A | E51: Water dispensor | F51: 2021 | H51: Nairobi | I51: Nairobi | K51: 16495 | L51: 0.125 | M51: =N51/(2025-F51) -> 1706.4835 | N51: =K51-O51 -> 6825.9338 | O51: =K51*(1-L51)^(2025-F51) -> 9669.0662 | R51: Elizabeth Kamau | S51: Good | T51: In Use
A52: Office equipments | B52: GOK | D52: NGOB/01/0230 | E52: Metal cabinet | F52: 2016 | H52: Eldoret | I52: Eldoret | K52: 22285 | L52: 0.125 | M52: =N52/(2025-F52) -> 1731.649 | N52: =K52-O52 -> 15584.841 | O52: =K52*(1-L52)^(2025-F52) -> 6700.1591 | R52: Carolyne Kimaiyo | S52: Good | T52: In Use
A53: Office equipments | B53: GOK | D53: NGOB/01/0231 | E53: Metal cabinet | F53: 2016 | H53: Eldoret | I53: Eldoret | K53: 22285 | L53: 0.125 | M53: =N53/(2025-F53) -> 1731.649 | N53: =K53-O53 -> 15584.841 | O53: =K53*(1-L53)^(2025-F53) -> 6700.1591 | R53: Carolyne Kimaiyo | S53: Good | T53: In Use
A54: Office equipments | B54: GOK | D54: NGOB/01/0232 | E54: Metal cabinet | F54: 2021 | H54: Eldoret | I54: Eldoret | K54: 34162 | L54: 0.125 | M54: =N54/(2025-F54) -> 3534.2157 | N54: =K54-O54 -> 14136.863 | O54: =K54*(1-L54)^(2025-F54) -> 20025.137 | R54: Carolyne Kimaiyo | S54: Good | T54: In Use
...

Sheet ICT Computer Register 
A1: ICT/Computer register
B2: Asset Description | C2: Financed by/ source of funds | D2: Serial number | E2: Tag number | F2: Make & Model | G2: Date of Delivery / installation | H2: PV number | I2: Original Location | J2: Current Location | K2: Replacement Date (if applicable) | L2: Purchase amount | M2: Depreciation rate | N2: Annual depreciation | O2: Accumulated depreciation | P2: Net Book Value | Q2: Date of disposal | R2: Disposal value | S2: Responsible officer | T2: Asset condition | U2: Notes
B3: CPU Monitor Keyboard | C3: GOK | D3: CZ018C7P 3CQ0030ZLZ | E3: NGOB/02/0230 NGOB/02/0239 NGOB/02/0038 | F3: HP PRODESK INTEL(R) CORE™I5-9500 4GB,500GB 17''inch LED HP Monitor | G3: 2020 | I3: Nairobi | J3: Nairobi | K3: 2023 | L3: 98000 | M3: 0.3 | N3: =O3/(2025-G3) -> 16305.828 | O3: =L3-P3 -> 81529.14 | P3: =L3*(1-M3)^(2025-G3) -> 16470.86 | S3: David Njane | T3: Good | U3: In use
B4: CPU Monitor Keyboard | C4: GOK | D4: CZC018C2FS 3CQ0030ZMB | E4: NGOB/02/0053 NGOB/02/0051 NGOB/02/0052 | F4: HP PRODESK INTEL(R) CORE™I5-9500 4GB,500GB 17''inch LED HP Monitor | G4: 2020 | I4: Nairobi | J4: Nairobi | K4: 2023 | L4: 98000 | M4: 0.3 | N4: =O4/(2025-G4) -> 16305.828 | O4: =L4-P4 -> 81529.14 | P4: =L4*(1-M4)^(2025-G4) -> 16470.86 | S4: Stephen Monyoncho | T4: Good | U4: In use
B5: CPU Monitor Keyboard | C5: GOK | D5: CZ018C2DG 3CQ0030W1V | E5: NGOB/02/0129 NGOB/02/0130 NGOB/02/0131 | F5: HP PRODESK INTEL(R) CORE™I5-9500 4GB,500GB 17''inch LED HP Monitor | G5: 2020 | I5: Nairobi | J5: Nairobi | K5: 2023 | L5: 98000 | M5: 0.3 | N5: =O5/(2025-G5) -> 16305.828 | O5: =L5-P5 -> 81529.14 | P5: =L5*(1-M5)^(2025-G5) -> 16470.86 | S5: Racheal Kimongo | T5: Good | U5: In use
B6: CPU Monitor Keyboard | C6: GOK | D6: CZ018CZ80 3CQ0030W1P | E6: NGOB/02/0053 NGOB/02/0073 NGOB/02/0083 | F6: HP PRODESK INTEL(R) CORE™I5-9500 4GB,500GB 17''inch LED HP Monitor | G6: 2020 | I6: Nairobi | J6: Nairobi | K6: 2023 | L6: 98000 | M6: 0.3 | N6: =O6/(2025-G6) -> 16305.828 | O6: =L6-P6 -> 81529.14 | P6: =L6*(1-M6)^(2025-G6) -> 16470.86 | S6: Steve Kamande | T6: Good | U6: In use
B7: CPU Monitor Keyboard | C7: GOK | D7: C2C018C510 3CQ0030ZKB | E7: NGOB/02/0220 NGOB/02/0219 NGOB/02/0221 | F7: HP PRODESK INTEL(R) CORE™I5-9500 4GB,500GB 17''inch LED HP Monitor | G7: 2020 | I7: Nairobi | J7: Nairobi | K7: 2023 | L7: 98000 | M7: 0.3 | N7: =O7/(2025-G7) -> 16305.828 | O7: =L7-P7 -> 81529.14 | P7: =L7*(1-M7)^(2025-G7) -> 16470.86 | S7: Arasa Mokua | T7: Good | U7: In use
B8: CPU Monitor Keyboard | C8: GOK | D8: C2C01807S 3CQ00312B7 | E8: NGOB/02/0217 NGOB/02/0216 NGOB/02/0218 | F8: HP PRODESK INTEL(R) CORE™I5-9500 4GB,500GB 17''inch LED HP Monitor | G8: 2020 | I8: Nairobi | J8: Nairobi | K8: 2023 | L8: 98000 | M8: 0.3 | N8: =O8/(2025-G8) -> 16305.828 | O8: =L8-P8 -> 81529.14 | P8: =L8*(1-M8)^(2025-G8) -> 16470.86 | S8: Dorris Muthini | T8: Good | U8: In use
B9: CPU Monitor Keyboard | C9: GOK | D9: CZCO18BYGK 3CQ0030Z8H | E9: NGOB/02/0028 NGOB/02/0029 NGOB/02/0030 | F9: HP PRODESK INTEL(R) CORE™I5-9500 4GB,500GB 17''inch LED HP Monitor | G9: 2020 | I9: Nairobi | J9: Nairobi | K9: 2023 | L9: 98000 | M9: 0.3 | N9: =O9/(2025-G9) -> 16305.828 | O9: =L9-P9 -> 81529.14 | P9: =L9*(1-M9)^(2025-G9) -> 16470.86 | S9: Eric Mutua | T9: Good | U9: In use
B10: CPU Monitor Keyboard | C10: GOK | D10: CZCO18BYK4 3CQ0030Z9H | E10: NGOB/02/0091 NGOB/02/0021 NGOB/02/0022 | F10: HP PRODESK INTEL(R) CORE™I5-9500 4GB,500GB 17''inch LED HP Monitor | G10: 2020 | I10: Nairobi | J10: Nairobi | K10: 2023 | L10: 98000 | M10: 0.3 | N10: =O10/(2025-G10) -> 16305.828 | O10: =L10-P10 -> 81529.14 | P10: =L10*(1-M10)^(2025-G10) -> 16470.86 | S10: Amina Matheka | T10: Good | U10: In use
B11: CPU Monitor Keyboard | C11: GOK | D11: CZCO18C2HJ 3CQ0030WC2 | E11: NGOB/02/0020 NGOB/02/0032 NGOB/02/0033 | F11: HP PRODESK INTEL(R) CORE™I5-9500 4GB,500GB 17''inch LED HP Monitor | G11: 2020 | I11: Nairobi | J11: Nairobi | K11: 2023 | L11: 98000 | M11: 0.3 | N11: =O11/(2025-G11) -> 16305.828 | O11: =L11-P11 -> 81529.14 | P11: =L11*(1-M11)^(2025-G11) -> 16470.86 | S11: Josephine Wanjala | T11: Good | U11: In use
B12: CPU Monitor Keyboard | C12: GOK | D12: CZCO18COBT 3CQ0031011 | E12: NGOB/02/0024 NGOB/02/0025 NGOB/02/0026 | F12: HP PRODESK INTEL(R) CORE™I5-9500 4GB,500GB 17''inch LED HP Monitor | G12: 2020 | I12: Nairobi | J12: Nairobi | K12: 2023 | L12: 98000 | M12: 0.3 | N12: =O12/(2025-G12) -> 16305.828 | O12: =L12-P12 -> 81529.14 | P12: =L12*(1-M12)^(2025-G12) -> 16470.86 | S12: Yvonne Ambundo | T12: Good | U12: In use
B13: CPU Monitor Keyboard | C13: GOK | D13: 4CE938205W 3CQ9191LJD | E13: NGOB/02/0159 NGOB/02/0158 NGOB/02/0160 | F13: HP PRODESK INTEL(R) CORE™I5-9500 4GB,500GB 17''inch LED HP Monitor | G13: 2020 | I13: Nairobi | J13: Nairobi | K13: 2023 | L13: 98000 | M13: 0.3 | N13: =O13/(2025-G13) -> 16305.828 | O13: =L13-P13 -> 81529.14 | P13: =L13*(1-M13)^(2025-G13) -> 16470.86 | S13: Juliet Karari | T13: Good | U13: In use
B14: CPU Monitor Keyboard | C14: GOK | D14: CZC018C28H 3CQ0031XQ1 | E14: NGOB/02/0024 NGOB/02/0025 NGOB/02/0026 | F14: HP PRODESK INTEL(R) CORE™I5-9500 4GB,500GB 17''inch LED HP Monitor | G14: 2020 | I14: Nairobi | J14: Nairobi | K14: 2023 | L14: 98000 | M14: 0.3 | N14: =O14/(2025-G14) -> 16305.828 | O14: =L14-P14 -> 81529.14 | P14: =L14*(1-M14)^(2025-G14) -> 16470.86 | S14: Scholar Mutua | T14: Good | U14: In use
... B40: CPU Monitor Keyboard | C40: GOK | D40: 7P6KB22 CN-OU417N-64180-98JOUMU | E40: NGOB/02/0210 NGOB/02/0209 NGOB/02/0211 | F40: HP PRO 3500 SERIES,INTEL CORE I3 3240, 4GB,500GB 17''inch LED HP Monitor | G40: 2008 | I40: Nairobi | J40: Nairobi | K40: 2011 | L40: 98000 | M40: 0.3 | N40: =O40/(2025-G40) -> 5751.2954 | O40: =L40-P40 -> 97772.022 | P40: =L40*(1-M40)^(2025-G40) -> 227.9779 | S40: HR Department | T40: Good | U40: In use
B41: CPU Monitor Keyboard | C41: GOK | E41: NGOB/02/0121 NGOB/02/0199 NGOB/02/0123 | F41: IMAC PRO | G41: 2020 | I41: Nairobi | J41: Nairobi | K41: 2023 | L41: 670000 | M41: 0.3 | N41: =O41/(2025-G41) -> 111478.62 | O41: =L41-P41 -> 557393.1 | P41: =L41*(1-M41)^(2025-G41) -> 112606.9 | S41: Richard Chesos | T41: Good | U41: In use
B42: CPU Monitor Keyboard | C42: GOK | D42: TRF415W2R 6CM4031GV6 | E42: NGOB/02/0043 NGOB/02/0248 | F42: HP PRO 3500 SERIES,INTEL CORE I3 3240, 4GB,500GB 17''inch LED HP Monitor | G42: 2015 | I42: Nairobi | J42: Nairobi | K42: 2018 | L42: 95042 | M42: 0.3 | N42: =O42/(2025-G42) -> 9235.7299 | O42: =L42-P42 -> 92357.299 | P42: =L42*(1-M42)^(2025-G42) -> 2684.7013 | S42: David Njane | T42: Good | U42: In use
B43: CPU Monitor Keyboard | C43: GOK | D43: CZCO18BYG6 3CQ0030Z96 | E43: NGOB/02/0044 NGOB/02/0046 NGOB/02/0048 | F43: INTEL CORE I3 4TH GENERATION,4GB, 500 GB 17''inch LED HP Monitor | G43: 2015 | I43: Nairobi | J43: Nairobi | K43: 2018 | L43: 95042 | M43: 0.3 | N43: =O43/(2025-G43) -> 9235.7299 | O43: =L43-P43 -> 92357.299 | P43: =L43*(1-M43)^(2025-G43) -> 2684.7013 | S43: Muktar Mohamed | T43: Good | U43: In use
B44: CPU Monitor Keyboard | C44: GOK | D44: DB3357 CN-OR735N-64180-9CJ-1HEAU | E44: NGOB/02/0162 NGOB/02/0056 NGOB/02/0163 | F44: INTEL CORE I3 4TH GENERATION,4GB, 500 GB 17''inch LED HP Monitor | G44: 2015 | I44: Nairobi | J44: Nairobi | K44: 2018 | L44: 95042 | M44: 0.3 | N44: =O44/(2025-G44) -> 9235.7299 | O44: =L44-P44 -> 92357.299 | P44: =L44*(1-M44)^(2025-G44) -> 2684.7013 | S44: Brian Oure | T44: Good | U44: In use
B45: CPU Monitor Keyboard | C45: GOK | D45: 5QQX232 CN-ONJVXM-72872-4BB-E00B | E45: NGOB/02/0155 NGOB/02/0154 NGOB/02/0156 | F45: DELL OPTIPLEX 3020 INTEL CORE I3 4GB,500GB 17''inch LED HDell Monitor | G45: 2015 | I45: Nairobi | J45: Nairobi | K45: 2018 | L45: 95042 | M45: 0.3 | N45: =O45/(2025-G45) -> 9235.7299 | O45: =L45-P45 -> 92357.299 | P45: =L45*(1-M45)^(2025-G45) -> 2684.7013 | S45: Mercy Soy | T45: Good | U45: In use
B46: CPU Monitor Keyboard | C46: GOK | D46: B3XY232 CN-ONJVXM-72872-4BB-DY5B | E46: NGOB/02/0055 NGOB/02/0016 NGOB/02/0009 | F46: DELL OPTIPLEX 3020 INTEL CORE I3 4GB,500GB 17''inch LED HP Monitor | G46: 2015 | I46: Nairobi | J46: Nairobi | K46: 2018 | L46: 95042 | M46: 0.3 | N46: =O46/(2025-G46) -> 9235.7299 | O46: =L46-P46 -> 92357.299 | P46: =L46*(1-M46)^(2025-G46) -> 2684.7013 | S46: Zulekha Siyat | T46: Good | U46: In use
B47: CPU Monitor Keyboard | C47: GOK | D47: 54XY23 CN-O65TPN-64880-512-8Y3I | E47: NGOB/02/0239 NGOB/02/0262 NGOB/02/0263 | F47: INTEL CORE I3 4TH GENERATION,4GB, 500 GB , 200 GB 17''inch LED HP Monitor | G47: 2015 | I47: Nairobi | J47: Nairobi | K47: 2018 | L47: 79494 | M47: 0.3 | N47: =O47/(2025-G47) -> 7724.8491 | O47: =L47-P47 -> 77248.491 | P47: =L47*(1-M47)^(2025-G47) -> 2245.5087 | S47: Duncan Mokaya | T47: Good | U47: In use
B48: CPU Monitor Keyboard | C48: GOK | D48: 2P25732 CN-0657PN-64180-512-A8GI | E48: NGOB/02/0173 NGOB/02/0005 NGOB/02/0 | F48: DELL OPTIPLEX 3020 INTEL CORE I3 4GB,500GB 17''inch LED Dell Monitor | G48: 2015 | I48: Nairobi | J48: Nairobi | K48: 2018 | L48: 79494 | M48: 0.3 | N48: =O48/(2025-G48) -> 7724.8491 | O48: =L48-P48 -> 77248.491 | P48: =L48*(1-M48)^(2025-G48) -> 2245.5087 | S48: Ephy Nafuna | T48: Good | U48: In use
B49: CPU Monitor Keyboard | C49: GOK | D49: 4CE93815X3 3CQ919KXR | E49: NGOB/02/0201 NGOB/02/0200 NGOB/02/0202 | F49: HP INTEL CORE I7 7th GENERATION ,4GB,500GB 17''inch LED HP Monitor | G49: 2020 | I49: Nairobi | J49: Nairobi | K49: 2023 | L49: 98000 | M49: 0.3 | N49: =O49/(2025-G49) -> 16305.828 | O49: =L49-P49 -> 81529.14 | P49: =L49*(1-M49)^(2025-G49) -> 16470.86 | S49: Payroll Server | T49: Good | U49: In use
B50: CPU Monitor Keyboard | C50: GOK | D50: 9F7KB22 CN-0R735N-64180-9CJ-04WU | E50: NGOB/02/0204 NGOB/02/0203 NGOB/02/0205 | F50: DELL OPTIPLEX 3020 INTEL CORE I3 4GB,500GB 17''inch LED Dell Monitor | G50: 2014 | I50: Nairobi | J50: Nairobi | K50: 2017 | L50: 55680 | M50: 0.3 | N50: =O50/(2025-G50) -> 4961.7295 | O50: =L50-P50 -> 54579.024 | P50: =L50*(1-M50)^(2025-G50) -> 1100.9755 | S50: Beryl Odete | T50: Good | U50: In use
B51: CPU Monitor Keyboard | C51: GOK | D51: BZ15732 CN-0657PN-64180-512-AAHI | E51: NGOB/02/0175 NGOB/02/0174 NGOB/02/0188 | F51: DELL OPTIPLEX 3020 INTEL CORE I3 4GB,500GB 17''inch LED Dell Monitor | G51: 2014 | I51: Nairobi | J51: Nairobi | K51: 2017 | L51: 55680 | M51: 0.3 | N51: =O51/(2025-G51) -> 4961.7295 | O51: =L51-P51 -> 54579.024 | P51: =L51*(1-M51)^(2025-G51) -> 1100.9755 | S51: Peter Ndale | T51: Good | U51: In use
B52: CPU Monitor Keyboard | C52: GOK | D52: 4CE9382O7F 3CQ851OGY6 | E52: NGOB/02/0135 NGOB/02/0136 NGOB/02/0137 | F52: HP PRO DESK400 G4, CORE I7 , 8GB,1TB MICRO TOWER PC 17''inch LED HP Monitor | G52: 2020 | I52: Nairobi | J52: Garissa | K52: 2023 | L52: 107500 | M52: 0.3 | N52: =O52/(2025-G52) -> 17886.495 | O52: =L52-P52 -> 89432.475 | P52: =L52*(1-M52)^(2025-G52) -> 18067.525 | S52: Garissa Office | T52: Good | U52: In use
B53: CPU Monitor Keyboard | C53: GOK | E53: NGOB/02/0228 NGOB/02/0329 NGOB/02/ | F53: HP PRO 3500 SERIES,INTEL CORE I3 3240, 4GB,500GB 21''inch LED HP Monitor | G53: 2008 | I53: Nairobi | J53: Nairobi | K53: 2011 | L53: 0 | M53: 0.3 | N53: =O53/(2025-G53) -> 0 | O53: =L53-P53 -> 0 | P53: =L53*(1-M53)^(2025-G53) -> 0 | S53: Joyce Naisiala | T53: Good | U53: In use
B54: LAPTOP COMPUTER | C54: GOK | D54: 5CD9135LHR | F54: HP Probook 450 G7, 10th Gen Core i7 Intel core, 16GB RAM DDR4, 1TB | G54: 2019 | I54: Nairobi | J54: Nairobi | K54: 2022 | L54: 125900 | M54: 0.3 | N54: =O54/(2025-G54) -> 18514.665 | O54: =L54-P54 -> 111087.99 | P54: =L54*(1-M54)^(2025-G54) -> 14812.009 | S54: Executive Director | T54: Good | U54: In use
B55: LAPTOP COMPUTER | C55: GOK | D55: 5CD0152R6G | F55: HP Probook 450 G7, 10th Gen Core i7 Intel core, 16GB RAM DDR4, 1TB | G55: 2020 | I55: Nairobi | J55: Nairobi | K55: 2023 | L55: 125900 | M55: 0.3 | N55: =O55/(2025-G55) -> 20947.997 | O55: =L55-P55 -> 104739.99 | P55: =L55*(1-M55)^(2025-G55) -> 21160.013 | S55: Deputy Executive Director | T55: Good | U55: In use
B56: LAPTOP COMPUTER | C56: GOK | D56: 5CD0152QZK | F56: HP Probook 450 G7, 10th Gen Core i7 Intel core, 16GB RAM DDR4, 1TB | G56: 2020 | I56: Nairobi | J56: Nairobi | K56: 2023 | L56: 125900 | M56: 0.3 | N56: =O56/(2025-G56) -> 20947.997 | O56: =L56-P56 -> 104739.99 | P56: =L56*(1-M56)^(2025-G56) -> 21160.013 | S56: David Njane | T56: Good | U56: In use
B57: LAPTOP COMPUTER | C57: GOK | D57: 5CD0152R5Y | E57: NGOB/02/0379 | F57: HP Probook 450 G7, 10th Gen Core i7 Intel core, 16GB RAM DDR4, 1TB | G57: 2020 | I57: Nairobi | J57: Nairobi | K57: 2023 | L57: 125900 | M57: 0.3 | N57: =O57/(2025-G57) -> 20947.997 | O57: =L57-P57 -> 104739.99 | P57: =L57*(1-M57)^(2025-G57) -> 21160.013 | S57: Joyce Naisiala | T57: Good | U57: In use
B58: LAPTOP COMPUTER | C58: GOK | D58: 5CD03590FZC | E58: NGOB/02/0023 | F58: HP Probook 450 G7, 10th Gen Core i7 Intel core, 16GB RAM DDR4, 1TB | G58: 2020 | I58: Nairobi | J58: Nairobi | K58: 2023 | L58: 125900 | M58: 0.3 | N58: =O58/(2025-G58) -> 20947.997 | O58: =L58-P58 -> 104739.99 | P58: =L58*(1-M58)^(2025-G58) -> 21160.013 | S58: Amina Matheka | T58: Good | U58: In use
B59: LAPTOP COMPUTER | C59: GOK | D59: 5CD0359OHM | E59: NGOB/02/0027 | F59: HP Probook 450 G7, 10th Gen Core i7 Intel core, 16GB RAM DDR4, 1TB | G59: 2020 | I59: Nairobi | J59: Nairobi | K59: 2023 | L59: 125900 | M59: 0.3 | N59: =O59/(2025-G59) -> 20947.997 | O59: =L59-P59 -> 104739.99 | P59: =L59*(1-M59)^(2025-G59) -> 21160.013 | S59: Yvonne Isichi | T59: Good | U59: In use
B60: LAPTOP COMPUTER | C60: GOK | D60: 5CD0359OHJC | E60: NGOB/02/0276 | F60: HP Probook 450 G7, 10th Gen Core i7 Intel core, 16GB RAM DDR4, 1TB | G60: 2020 | I60: Nairobi | J60: Nairobi | K60: 2023 | L60: 125900 | M60: 0.3 | N60: =O60/(2025-G60) -> 20947.997 | O60: =L60-P60 -> 104739.99 | P60: =L60*(1-M60)^(2025-G60) -> 21160.013 | S60: Josephine Wanjala | T60: Good | U60: In use
B61: LAPTOP COMPUTER | C61: GOK | D61: 5CD0359OJMC | F61: HP Probook 450 G7, 10th Gen Core i7 Intel core, 16GB RAM DDR4, 1TB | G61: 2020 | I61: Nairobi | J61: Nairobi | K61: 2023 | L61: 125900 | M61: 0.3 | N61: =O61/(2025-G61) -> 20947.997 | O61: =L61-P61 -> 104739.99 | P61: =L61*(1-M61)^(2025-G61) -> 21160.013 | S61: Zilpah Kwamboka | T61: Good | U61: In use
B62: LAPTOP COMPUTER | C62: GOK | D62: 5CD0359OH4C | F62: HP Probook 450 G7, 10th Gen Core i7 Intel core, 16GB RAM DDR4, 1TB | G62: 2020 | I62: Nairobi | J62: Nairobi | K62: 2023 | L62: 125900 | M62: 0.3 | N62: =O62/(2025-G62) -> 20947.997 | O62: =L62-P62 -> 104739.99 | P62: =L62*(1-M62)^(2025-G62) -> 21160.013 | S62: Caroline Nyambura | T62: Good | U62: In use
B63: LAPTOP COMPUTER | C63: GOK | D63: 5CD0359OJ4 | F63: HP Probook 450 G7, 10th Gen Core i7 Intel core, 16GB RAM DDR4, 1TB | G63: 2020 | I63: Nairobi | J63: Nairobi | K63: 2023 | L63: 125900 | M63: 0.3 | N63: =O63/(2025-G63) -> 20947.997 | O63: =L63-P63 -> 104739.99 | P63: =L63*(1-M63)^(2025-G63) -> 21160.013 | S63: Isaiah Sang | T63: Good | U63: In use
B64: LAPTOP COMPUTER | C64: GOK | D64: 5CD0359OGWC | F64: HP Probook 450 G7, 10th Gen Core i7 Intel core, 16GB RAM DDR4, 1TB | G64: 2020 | I64: Nairobi | J64: Nairobi | K64: 2023 | L64: 125900 | M64: 0.3 | N64: =O64/(2025-G64) -> 20947.997 | O64: =L64-P64 -> 104739.99 | P64: =L64*(1-M64)^(2025-G64) -> 21160.013 | S64: Beryl Odete | T64: Good | U64: In use
B65: LAPTOP COMPUTER | C65: GOK | D65: 5CD0359OHCC | F65: HP Probook 450 G7, 10th Gen Core i7 Intel core, 16GB RAM DDR4, 1TB | G65: 2020 | I65: Nairobi | J65: Nairobi | K65: 2023 | L65: 125900 | M65: 0.3 | N65: =O65/(2025-G65) -> 20947.997 | O65: =L65-P65 -> 104739.99 | P65: =L65*(1-M65)^(2025-G65) -> 21160.013 | S65: Bernard Bwoma | T65: Good | U65: In use
...

Sheet Furniture&Fittings 
A1: Asset Description | B1: Financed by/ source of funds | C1: Serial number | D1: Tag number | E1: Make & Model | F1: Date of Delivery / installation | G1: PV number | H1: Original Location | I1: Current Location | J1: Replacement Date (if applicable) | K1: Purchase amount | L1: Depreciation rate | M1: Annual depreciation | N1: Accumulated depreciation | O1: Net Book Value | P1: Date of disposal | Q1: Disposal value | R1: Responsible officer | S1: Asset condition
A2: Office Desk | B2: GOK | C2: N/A | D2: NGOB/01/0342 | E2: L-Shaped W/S 1.8 m | F2: 2005 | H2: Nairobi | I2: Nairobi | J2: 2014 | K2: 16300 | L2: 0.125 | M2: =O2/(2025-F2) -> 56.405138 | N2: =K2-O2 -> 15171.897 | O2: =K2*(1-L2)^(2025-F2) -> 1128.1028 | R2: Joyce Naisiala | S2: Good
A3: Office Desk | B3: GOK | C3: N/A | D3: NGOB/01/0286 | E3: L-Shaped W/S 1.8 m | F3: 2005 | H3: Nairobi | I3: Nairobi | J3: 2014 | K3: 16300 | L3: 0.125 | M3: =O3/(2025-F3) -> 56.405138 | N3: =K3-O3 -> 15171.897 | O3: =K3*(1-L3)^(2025-F3) -> 1128.1028 | R3: Elizabeth Kamau | S3: Good
A4: Office Desk | B4: GOK | C4: N/A | D4: NGOB/01/0127 | E4: L-Shaped W/S 1.8 m | F4: 2005 | H4: Nairobi | I4: Nairobi | J4: 2014 | K4: 16300 | L4: 0.125 | M4: =O4/(2025-F4) -> 56.405138 | N4: =K4-O4 -> 15171.897 | O4: =K4*(1-L4)^(2025-F4) -> 1128.1028 | R4: Administration department | S4: Good
A5: Office Desk | B5: GOK | C5: N/A | D5: NGOB/01/0120 | E5: L-Shaped W/S 1.8 m | F5: 2005 | H5: Nairobi | I5: Nairobi | J5: 2014 | K5: 16300 | L5: 0.125 | M5: =O5/(2025-F5) -> 56.405138 | N5: =K5-O5 -> 15171.897 | O5: =K5*(1-L5)^(2025-F5) -> 1128.1028 | R5: Nick Sankale | S5: Good
A6: Office Desk | B6: GOK | C6: N/A | D6: NGOB/01/0019 | E6: L-Shaped W/S 1.8 m | F6: 2005 | H6: Nairobi | I6: Nairobi | J6: 2014 | K6: 16300 | L6: 0.125 | M6: =O6/(2025-F6) -> 56.405138 | N6: =K6-O6 -> 15171.897 | O6: =K6*(1-L6)^(2025-F6) -> 1128.1028 | R6: Ephy Nafuna | S6: Good
A7: Office Desk | B7: GOK | C7: N/A | D7: NGOB/01/0075 | E7: L-Shaped W/S 1.8 m | F7: 2005 | H7: Nairobi | I7: Nairobi | J7: 2014 | K7: 16300 | L7: 0.125 | M7: =O7/(2025-F7) -> 56.405138 | N7: =K7-O7 -> 15171.897 | O7: =K7*(1-L7)^(2025-F7) -> 1128.1028 | R7: Carolyne Nyambura | S7: Good
A8: Office Desk | B8: GOK | C8: N/A | D8: NGOB/01/0500 | E8: L-Shaped W/S 1.8 m | F8: 2005 | H8: Nairobi | I8: Nairobi | J8: 2014 | K8: 16300 | L8: 0.125 | M8: =O8/(2025-F8) -> 56.405138 | N8: =K8-O8 -> 15171.897 | O8: =K8*(1-L8)^(2025-F8) -> 1128.1028 | R8: Bernadette Nzomo | S8: Good
A9: Office Desk | B9: GOK | C9: N/A | D9: NGOB/01/0493 | E9: L-Shaped W/S 1.8 m | F9: 2005 | H9: Nairobi | I9: Nairobi | J9: 2014 | K9: 16300 | L9: 0.125 | M9: =O9/(2025-F9) -> 56.405138 | N9: =K9-O9 -> 15171.897 | O9: =K9*(1-L9)^(2025-F9) -> 1128.1028 | R9: Stephen Monyoncho | S9: Good
A10: Office Desk | B10: GOK | C10: N/A | D10: NGOB/01/0018 | E10: L-Shaped W/S 1.8 m | F10: 2005 | H10: Nairobi | I10: Nairobi | J10: 2014 | K10: 16300 | L10: 0.125 | M10: =O10/(2025-F10) -> 56.405138 | N10: =K10-O10 -> 15171.897 | O10: =K10*(1-L10)^(2025-F10) -> 1128.1028 | R10: Margaret Mwai | S10: Good
A11: Mobile Drawers | B11: GOK | C11: N/A | D11: NGOB/01/0343 | E11: Four drawers | F11: 2005 | H11: Nairobi | I11: Nairobi | J11: 2014 | K11: 9100 | L11: 0.125 | M11: =O11/(2025-F11) -> 31.489985 | N11: =K11-O11 -> 8470.2003 | O11: =K11*(1-L11)^(2025-F11) -> 629.7997 | R11: Joyce Naisiala | S11: Good
A12: Mobile Drawers | B12: GOK | C12: N/A | D12: NGOB/01/0266 | E12: Four drawers | F12: 2005 | H12: Nairobi | I12: Nairobi | J12: 2014 | K12: 9100 | L12: 0.125 | M12: =O12/(2025-F12) -> 31.489985 | N12: =K12-O12 -> 8470.2003 | O12: =K12*(1-L12)^(2025-F12) -> 629.7997 | R12: Lindon Otieno | S12: Good
A13: Mobile Drawers | B13: GOK | C13: N/A | D13: NGOB/01/0116 | E13: Four drawers | F13: 2005 | H13: Nairobi | I13: Nairobi | J13: 2014 | K13: 9100 | L13: 0.125 | M13: =O13/(2025-F13) -> 31.489985 | N13: =K13-O13 -> 8470.2003 | O13: =K13*(1-L13)^(2025-F13) -> 629.7997 | R13: Aisha Mohammed | S13: Good
... A27: Suspension Drawers | B27: GOK | C27: N/A | D27: NGOB/01/0126 | E27: 3 drawer pedestrial | F27: 2005 | H27: Nairobi | I27: Nairobi | J27: 2014 | K27: 5880 | L27: 0.125 | M27: =O27/(2025-F27) -> 20.347375 | N27: =K27-O27 -> 5473.0525 | O27: =K27*(1-L27)^(2025-F27) -> 406.9475 | R27: Beatrice Topisa | S27: Good
A28: Suspension Drawers | B28: GOK | D28: NGOB/01/0272 | E28: 3 drawer pedestrial | F28: 2005 | H28: Nairobi | I28: Nairobi | J28: 2014 | K28: 5880 | L28: 0.125 | M28: =O28/(2025-F28) -> 20.347375 | N28: =K28-O28 -> 5473.0525 | O28: =K28*(1-L28)^(2025-F28) -> 406.9475 | R28: Mercy Soy | S28: Good
A29: Suspension Drawers | B29: GOK | D29: NGOB/01/0291 | E29: 3 drawer pedestrial | F29: 2005 | H29: Nairobi | I29: Nairobi | J29: 2014 | K29: 5880 | L29: 0.125 | M29: =O29/(2025-F29) -> 20.347375 | N29: =K29-O29 -> 5473.0525 | O29: =K29*(1-L29)^(2025-F29) -> 406.9475 | R29: Elizabeth Kamau | S29: Good
A30: Side Return | B30: GOK | C30: N/A | D30: NGOB/01/0049 | E30: Side return | F30: 2005 | H30: Nairobi | I30: Nairobi | J30: 2014 | K30: 8120 | L30: 0.125 | M30: =O30/(2025-F30) -> 28.098756 | N30: =K30-O30 -> 7558.0249 | O30: =K30*(1-L30)^(2025-F30) -> 561.97512 | R30: Andrew Ogombe | S30: Good
A31: Side Return | B31: GOK | C31: N/A | D31: NGOB/01/0110 | E31: Side return | F31: 2005 | H31: Nairobi | I31: Nairobi | J31: 2014 | K31: 8120 | L31: 0.125 | M31: =O31/(2025-F31) -> 28.098756 | N31: =K31-O31 -> 7558.0249 | O31: =K31*(1-L31)^(2025-F31) -> 561.97512 | R31: Margaret Mwai | S31: Good
A32: Side Return | B32: GOK | C32: N/A | D32: NGOB/01/0445 | E32: Side return | F32: 2005 | H32: Nairobi | I32: Nairobi | J32: 2014 | K32: 8120 | L32: 0.125 | M32: =O32/(2025-F32) -> 28.098756 | N32: =K32-O32 -> 7558.0249 | O32: =K32*(1-L32)^(2025-F32) -> 561.97512 | R32: Charles Mugo | S32: Good
A33: Side Return | B33: GOK | C33: N/A | D33: NGOB/01/0097 | E33: Side return | F33: 2005 | H33: Nairobi | I33: Nairobi | J33: 2014 | K33: 8120 | L33: 0.125 | M33: =O33/(2025-F33) -> 28.098756 | N33: =K33-O33 -> 7558.0249 | O33: =K33*(1-L33)^(2025-F33) -> 561.97512 | R33: Charles Mugo | S33: Good
A34: Side Return | B34: GOK | C34: N/A | D34: NGOB/01/0346 | E34: Side return | F34: 2005 | H34: Nairobi | I34: Nairobi | J34: 2014 | K34: 8120 | L34: 0.125 | M34: =O34/(2025-F34) -> 28.098756 | N34: =K34-O34 -> 7558.0249 | O34: =K34*(1-L34)^(2025-F34) -> 561.97512 | R34: Joyce Naisiala | S34: Good
A35: Side Return | B35: GOK | C35: N/A | D35: N/A | E35: Side return | F35: 2005 | H35: Nairobi | I35: Nairobi | J35: 2014 | K35: 8120 | L35: 0.125 | M35: =O35/(2025-F35) -> 28.098756 | N35: =K35-O35 -> 7558.0249 | O35: =K35*(1-L35)^(2025-F35) -> 561.97512 | R35: Administration department | S35: Good
A36: Side Return | B36: GOK | C36: N/A | D36: N/A | E36: Side return | F36: 2005 | H36: Nairobi | I36: Nairobi | J36: 2014 | K36: 8120 | L36: 0.125 | M36: =O36/(2025-F36) -> 28.098756 | N36: =K36-O36 -> 7558.0249 | O36: =K36*(1-L36)^(2025-F36) -> 561.97512 | R36: Administration department | S36: Good
A37: Desktop Screen | B37: GOK | C37: N/A | D37: N/A | E37: Desktop Screen | F37: 2005 | H37: Nairobi | I37: Nairobi | J37: 2014 | K37: 4060 | L37: 0.125 | M37: =O37/(2025-F37) -> 14.049378 | N37: =K37-O37 -> 3779.0124 | O37: =K37*(1-L37)^(2025-F37) -> 280.98756 | R37: Administration department | S37: Good
A38: Desktop Screen | B38: GOK | C38: N/A | D38: N/A | E38: Desktop Screen | F38: 2005 | H38: Nairobi | I38: Nairobi | J38: 2014 | K38: 4060 | L38: 0.125 | M38: =O38/(2025-F38) -> 14.049378 | N38: =K38-O38 -> 3779.0124 | O38: =K38*(1-L38)^(2025-F38) -> 280.98756 | R38: Administration department | S38: Good
A39: L shape work station | B39: GOK | C39: N/A | D39: NGOB/01/0396 | E39: L shape work station | F39: 2005 | H39: Nairobi | I39: Nairobi | J39: 2014 | K39: 14350 | L39: 0.125 | M39: =O39/(2025-F39) -> 49.657284 | N39: =K39-O39 -> 13356.854 | O39: =K39*(1-L39)^(2025-F39) -> 993.14569 | R39: Berly Odete | S39: Good
A40: L shape work station | B40: GOK | C40: N/A | D40: NGOB/01/0377 | E40: L shape work station | F40: 2005 | H40: Nairobi | I40: Nairobi | J40: 2014 | K40: 14350 | L40: 0.125 | M40: =O40/(2025-F40) -> 49.657284 | N40: =K40-O40 -> 13356.854 | O40: =K40*(1-L40)^(2025-F40) -> 993.14569 | R40: Aisha Mohammed | S40: Good
A41: L shape work station | B41: GOK | C41: N/A | D41: NGOB/01/0350 | E41: L shape work station | F41: 2005 | H41: Nairobi | I41: Nairobi | J41: 2014 | K41: 14350 | L41: 0.125 | M41: =O41/(2025-F41) -> 49.657284 | N41: =K41-O41 -> 13356.854 | O41: =K41*(1-L41)^(2025-F41) -> 993.14569 | R41: Mukhtar Mohamed
A42: L shape work station | B42: GOK | C42: N/A | D42: NGOB/01/0359 | E42: L shape work station | F42: 2005 | H42: Nairobi | I42: Nairobi | J42: 2014 | K42: 14350 | L42: 0.125 | M42: =O42/(2025-F42) -> 49.657284 | N42: =K42-O42 -> 13356.854 | O42: =K42*(1-L42)^(2025-F42) -> 993.14569 | R42: Easther Letting | S42: Good
A43: L shape work station | B43: GOK | C43: N/A | D43: NGOB/01/0351 | E43: L shape work station | F43: 2005 | H43: Nairobi | I43: Nairobi | J43: 2014 | K43: 14350 | L43: 0.125 | M43: =O43/(2025-F43) -> 49.657284 | N43: =K43-O43 -> 13356.854 | O43: =K43*(1-L43)^(2025-F43) -> 993.14569 | R43: Allan Gashoka | S43: Good
A44: L shape work station | B44: GOK | C44: N/A | D44: NGOB/01/0271 | E44: L shape work station | F44: 2005 | H44: Nairobi | I44: Nairobi | J44: 2014 | K44: 14350 | L44: 0.125 | M44: =O44/(2025-F44) -> 49.657284 | N44: =K44-O44 -> 13356.854 | O44: =K44*(1-L44)^(2025-F44) -> 993.14569 | R44: Mercy Soy | S44: Good
A45: L shape work station | B45: GOK | C45: N/A | D45: NGOB/01/0398 | E45: L shape work station | F45: 2005 | H45: Nairobi | I45: Nairobi | J45: 2014 | K45: 14350 | L45: 0.125 | M45: =O45/(2025-F45) -> 49.657284 | N45: =K45-O45 -> 13356.854 | O45: =K45*(1-L45)^(2025-F45) -> 993.14569 | R45: Beatrice Topisa | S45: Good
A46: L shape work station | B46: GOK | C46: N/A | D46: NGOB/01/0382 | E46: L shape work station | F46: 2005 | H46: Nairobi | I46: Nairobi | J46: 2014 | K46: 14350 | L46: 0.125 | M46: =O46/(2025-F46) -> 49.657284 | N46: =K46-O46 -> 13356.854 | O46: =K46*(1-L46)^(2025-F46) -> 993.14569 | R46: Juliet Karari | S46: Good
A47: L shape work station | B47: GOK | C47: N/A | D47: NGOB/01/0326 | E47: L shape work station | F47: 2005 | H47: Nairobi | I47: Nairobi | J47: 2014 | K47: 14350 | L47: 0.125 | M47: =O47/(2025-F47) -> 49.657284 | N47: =K47-O47 -> 13356.854 | O47: =K47*(1-L47)^(2025-F47) -> 993.14569 | R47: Dorris Muthini | S47: Good
A48: Pedestrial mobile | B48: GOK | C48: N/A | D48: NGOB/01/0131 | E48: Four drawers | F48: 2005 | H48: Nairobi | I48: Nairobi | J48: 2014 | K48: 9100 | L48: 0.125 | M48: =O48/(2025-F48) -> 31.489985 | N48: =K48-O48 -> 8470.2003 | O48: =K48*(1-L48)^(2025-F48) -> 629.7997 | R48: Ezna Moriasi | S48: Good
A49: Pedestrial mobile | B49: GOK | C49: N/A | D49: NGOB/01/0121 | E49: Four drawers | F49: 2005 | H49: Nairobi | I49: Nairobi | J49: 2014 | K49: 9100 | L49: 0.125 | M49: =O49/(2025-F49) -> 31.489985 | N49: =K49-O49 -> 8470.2003 | O49: =K49*(1-L49)^(2025-F49) -> 629.7997 | R49: Eric Wainaina | S49: Good
A50: Pedestrial mobile | B50: GOK | C50: N/A | D50: NGOB/01/0111 | E50: Four drawers | F50: 2005 | H50: Nairobi | I50: Nairobi | J50: 2014 | K50: 9100 | L50: 0.125 | M50: =O50/(2025-F50) -> 31.489985 | N50: =K50-O50 -> 8470.2003 | O50: =K50*(1-L50)^(2025-F50) -> 629.7997 | R50: Stephen Kamande | S50: Good
A51: Pedestrial mobile | B51: GOK | C51: N/A | D51: NGOB/01/0494 | E51: Four drawers | F51: 2005 | H51: Nairobi | I51: Nairobi | J51: 2014 | K51: 9100 | L51: 0.125 | M51: =O51/(2025-F51) -> 31.489985 | N51: =K51-O51 -> 8470.2003 | O51: =K51*(1-L51)^(2025-F51) -> 629.7997 | R51: Stephen Monyoncho | S51: Good
A52: Office Chairs | B52: GOK | C52: N/A | D52: NGOB/01/0329 | E52: High back swivel | F52: 2005 | H52: Nairobi | I52: Nairobi | J52: 2014 | K52: 6790 | L52: 0.125 | M52: =O52/(2025-F52) -> 23.496374 | N52: =K52-O52 -> 6320.0725 | O52: =K52*(1-L52)^(2025-F52) -> 469.92747 | R52: Dorris Muthini | S52: Good
A53: Office Chairs | B53: GOK | C53: N/A | D53: NGOB/01/0390 | E53: High back swivel | F53: 2005 | H53: Nairobi | I53: Nairobi | J53: 2014 | K53: 6790 | L53: 0.125 | M53: =O53/(2025-F53) -> 23.496374 | N53: =K53-O53 -> 6320.0725 | O53: =K53*(1-L53)^(2025-F53) -> 469.92747 | R53: Satra Hassan | S53: Good
...

Sheet Plant &Machinery Register
A1: Plant & Machinery
B2: Asset Description | C2: Financed by/ source of funds | D2: Serial number | E2: Tag number | F2: Make & Model | G2: Date of Delivery / installation | H2: PV number | I2: Original Location | J2: Current Location | K2: Replacement Date (if applicable) | L2: Purchase amount | M2: Depreciation rate | N2: Annual depreciation | O2: Accumulated depreciation | P2: Net Book Value | Q2: Date of disposal | R2: Disposal value | S2: Responsible officer | T2: Asset condition | U2: Notes
A3: 1 | B3: None | C3: None | D3: None | E3: None | F3: None | G3: None | H3: None | I3: None | J3: None | K3: None | L3: None | M3: None | N3: None | O3: None | P3: None | Q3: None | R3: None | S3: None | T3: None | U3: None | V3: None | W3: None | X3: None | Y3: None | Z3: None
A4: 2
A5: 3
A6: 4
A7: 5
A8: 6
A9: 7
A10: 8
A11: 9
A14: Prepared by: Doris Muthini Designation: Manager SCM Date: 30th June 2025
A15: Checked by: David NjaneDesignation: Finance Manager Date: 30th June 2025
A16: Authorized by: Dr. Laxmana P. Kiptoo Designation: Director/Chief Executive Officer Date: 30th June 2025

Sheet Portable &attractive Items 
A1: Portable &attractive items
B2: Asset Description | C2: Financed by/ source of funds | D2: Serial number | E2: Tag number | F2: Make & Model | G2: Date of Delivery / installation | H2: PV number | I2: Original Location | J2: Current Location | K2: Replacement Date (if applicable) | L2: Purchase amount | M2: Depreciation rate | N2: Annual depreciation | O2: Accumulated depreciation | P2: Net Book Value | Q2: Date of disposal | R2: Disposal value | S2: Responsible officer | T2: Asset condition | U2: Notes
A3: 1 | B3: None | C3: None | D3: None | E3: None | F3: None | G3: None | H3: None | I3: None | J3: None | K3: None | L3: None | M3: None | N3: None | O3: None | P3: None | Q3: None | R3: None | S3: None | T3: None | U3: None | V3: None | W3: None | X3: None | Y3: None | Z3: None
A4: 2
A5: 3
A6: 4
A7: 5
A8: 6
A9: 7
A10: 8
A11: 9
A14: Prepared by: Doris Muthini Designation: Manager SCM Date: 30th June 2025
A15: Checked by: David NjaneDesignation: Finance Manager Date: 30th June 2025
A16: Authorized by: Dr. Laxmana P. Kiptoo Designation: Director/Chief Executive Officer Date: 30th June 2025

Sheet Intangible Asset Register 
A1: Intangible Assets Register
B2: Asset description/ Nature of asset | C2: Document of ownership | D2: Acquired from | E2: Cost/ Fair value | F2: Useful life | G2: Annual depreciation/armotisation | H2: Accumulated depreciation/armotisation | I2: Net Book value | J2: Remarks
A3: 1 | B3: Eset Antivirus | C3: PBORA-Key | D3: Comtech Limited | E3: 268534.2 | F3: One Year | G3: N/A | H3: N/A | I3: 100317.04
A4: 2 | B4: Google Emails | C4: Contract | D4: Cloud IT Limited | E4: 1265432.4 | F4: One Year | G4: N/A | H4: N/A | I4: 822960
A5: 3 | B5: Internet | C5: Contract | D5: Dimension Data Solutions (E.A) Limited | E5: 2095586.4 | F5: One Year | G5: N/A | H5: N/A | I5: 1932096
A6: 4 | I6: =SUM(I3:I5) -> 2855373
A7: 5 | B7: TOTAL
A8: 6
A9: 7
A10: 8
A11: 9
A13: Prepared by: Yvonne Gitau Designation: ICT Officer Date: 30th June 2025
A14: Checked by: Francis Tumuti Designation: Principal ICT Officer Date:30th June 2025
A15: Authorized by: Dr. Laxmana P. Kiptoo Designation: Director/Chief Executive Officer Date: 30th June 2025

Sheet Stocks Consumables Register 
A1: Stocks/ Consumables Register
A2: Description of inventory item | B2: Unit e.g piece, Kgs, etc. | C2: Quantity | D2: Unit+E3:F22 cost | E2: Total Cost | F2: Responsible officer | G2: Remarks
A3: Box File | B3: PIECES | C3: 230 | D3: 350 | E3: 80500 | F3: Arasa Mokuah | G3: Closing stocks as at 30TH JUNE2025
A4: Coloured photocopying Papers Blue | B4: PIECES | C4: 50 | D4: 1650 | E4: 82500 | F4: Arasa Mokuah | G4: Closing stocks as at 30TH JUNE2025
A5: Coloured photocopying Papers Pink | B5: PIECES | C5: 25 | D5: 1679 | E5: 41975 | F5: Arasa Mokuah | G5: Closing stocks as at 30TH JUNE2025
A6: Document folder | B6: PIECES | C6: 1256 | D6: 65 | E6: 81640 | F6: Arasa Mokuah | G6: Closing stocks as at 30TH JUNE2025
A7: ENEVELOPES A4 | B7: PIECES | C7: 350 | D7: 14 | E7: 4900 | F7: Arasa Mokuah | G7: Closing stocks as at 30TH JUNE2025
A8: ENVELOPES A5 | B8: PIECES | C8: 1000 | D8: 5 | E8: 5000 | F8: Arasa Mokuah | G8: Closing stocks as at 30TH JUNE2025
A9: COPY CAT TONER NO 2501 | B9: PIECES | C9: 5 | D9: 5035 | E9: 25175 | F9: Arasa Mokuah | G9: Closing stocks as at 30TH JUNE2025
A10: GLUE PASTE | B10: DOZENS | C10: 6 | D10: 3328.8 | E10: 19972.8 | F10: Arasa Mokuah | G10: Closing stocks as at 30TH JUNE2025
A11: PAPER PUNCH | B11: PIECES | C11: 5 | D11: 1600 | E11: 8000 | F11: Arasa Mokuah | G11: Closing stocks as at 30TH JUNE2025
A12: GLOBE SPRING FILE | B12: BOX | C12: 18 | D12: 11050 | E12: 198900 | F12: Arasa Mokuah | G12: Closing stocks as at 30TH JUNE2025
A13: PHOTOCOPYING PAPERS | B13: PIECES | C13: 220 | D13: 1195 | E13: 262900 | F13: Arasa Mokuah | G13: Closing stocks as at 30TH JUNE2025
A14: REGISTRATION FORMS(Form 2) | B14: REAMS | C14: 6 | D14: 4700 | E14: 28200 | F14: Arasa Mokuah | G14: Closing stocks as at 30TH JUNE2025
... A24: TONER NO 411 | B24: PIECES | C24: 1 | D24: 30250 | E24: 30250 | F24: Arasa Mokuah | G24: Closing stocks as at 30TH JUNE2025
A25: TONER NO 412 | B25: PIECES | C25: 1 | D25: 30250 | E25: =D25 -> 30250 | F25: Arasa Mokuah | G25: Closing stocks as at 30TH JUNE2025
A26: TONER NO 413 | B26: PIECES | C26: 1 | D26: 30250 | E26: =D26 -> 30250 | F26: Arasa Mokuah | G26: Closing stocks as at 30TH JUNE2025
A27: TONER NO TK-475 | B27: PIECES | C27: 4 | D27: 10000 | E27: 40000 | F27: Arasa Mokuah | G27: Closing stocks as at 30TH JUNE2025
A28: TONER NO1160 | B28: PIECES | C28: 4 | D28: 7000 | E28: 28000 | F28: Arasa Mokuah | G28: Closing stocks as at 30TH JUNE2025
A29: STAPLERS PINS | B29: PACKETS | C29: 3 | D29: 1350 | E29: 4050 | F29: Arasa Mokuah | G29: Closing stocks as at 30TH JUNE2025
A30: HIGHLIGHTERS | B30: DOZENS | C30: 33 | D30: 900 | E30: 29700 | F30: Arasa Mokuah | G30: Closing stocks as at 30TH JUNE2025
A31: STICKY NOTES | B31: DOZENS | C31: 36 | D31: 670 | E31: 24120 | F31: Arasa Mokuah | G31: Closing stocks as at 30TH JUNE2025
A32: MASKING TAPES | B32: PIECES | C32: 24 | D32: 195 | E32: 4680 | F32: Arasa Mokuah | G32: Closing stocks as at 30TH JUNE2025
A33: STAPLERS | B33: PIECES | C33: 1 | D33: 1350 | E33: 1350 | F33: Arasa Mokuah | G33: Closing stocks as at 30TH JUNE2025
A34: BIC BIROS | B34: PACKETS | C34: 20 | D34: 560 | E34: 11200 | F34: Arasa Mokuah | G34: Closing stocks as at 30TH JUNE2025
A35: TOTALS | E35: =SUM(E3:E34) -> 1553162.8
A38: Prepared by: Arasa Mokuah Designation: SCM Officer Date: 30th June 2025
A39: Checked by: Doris Muthini Designation: Manager SCM Date: 30th June 2025
A40: Authorized by: Dr. Laxmana P. Kiptoo Designation: Director/Chief Executive Officer Date: 30th June 2025

Sheet Railway register 
A1: Railways Register
B2: Railway description | C2: Railway ID | D2: Length (Kms) | E2: Date of commissioning | F2: Type of rail | G2: Amenities available | H2: Land registry ID | I2: Useful life | J2: Cost | K2: Annual depreciation | L2: Accumulated depreciation | M2: Net Book value | N2: Remarks
A3: 1 | B3: None | C3: None | D3: None | E3: None | F3: None | G3: None | H3: None | I3: None | J3: None | K3: None | L3: None | M3: None | N3: None
A4: 2
A5: 3
A6: 4
A7: 5
A8: 6
A9: 7
A10: 8
A11: 9
A13: Prepared by: Doris Muthini Designation: Manager SCM Date: 30th June 2025
A14: Checked by: David NjaneDesignation: Finance Manager Date: 30th June 2025
A15: Authorized by: Dr. Laxmana P. Kiptoo Designation: Director/Chief Executive Officer Date: 30th June 2025

Sheet Roads Infastructure register 
A1: Roads Infrastructure Register
B2: Road description | C2: Road ID | D2: Length (Kms) | E2: Date of commissioning | F2: Type of road e.g. bitumen, earth etc. | G2: Class of road e.g. A,B,C,D etc. | H2: Mode of funding e.g PPP, GoK, external funding etc. | I2: Amenities available | J2: Land registry ID | K2: Useful life | L2: Cost | M2: Annual depreciation | N2: Accumulated depreciation | O2: Net Book value | P2: Remarks
A3: 1 | B3: None | C3: None | D3: None | E3: None | F3: None | G3: None | H3: None | I3: None | J3: None | K3: None | L3: None | M3: None | N3: None | O3: None | P3: None
A4: 2
A5: 3
A6: 4
A7: 5
A8: 6
A11: Prepared by: Doris Muthini Designation: Manager SCM Date: 30th June 2025
A12: Checked by: David NjaneDesignation: Finance Manager Date: 30th June 2025
A13: Authorized by: Dr. Laxmana P. Kiptoo Designation: Director/Chief Executive Officer Date: 30th June 2025

